Workbook

Sheet Charts

Sheet Calcs 1
A2: RETENTION CURVE | C2: 1 | D2: =C2+1 -> 2 | E2: =D2+1 -> 3 | F2: =E2+1 -> 4 | G2: =F2+1 -> 5 | H2: =G2+1 -> 6 | I2: =H2+1 -> 7 | J2: =I2+1 -> 8 | K2: =J2+1 -> 9 | ... Z2: =Y2+1 -> 24
A3: Leaky Bucket | C3: 1 | D3: 0.95462308 | E3: 0.91130523 | F3: 0.86995301 | G3: 0.83047723 | H3: 0.79279273 | I3: 0.75681824 | J3: 0.72247616 | K3: 0.68969242 | L3: 0.65839631 | M3: 0.62852031 | N3: 0.6 | O3: 0.58578695 | P3: 0.57191058 | Q3: 0.55836292 | R3: 0.54513618 | S3: 0.53222276 | T3: 0.51961524 | U3: 0.50730638 | V3: 0.49528909 | W3: 0.48355647 | X3: 0.47210178 | Y3: 0.46091843 | Z3: 0.45
A4: Net Negative | C4: 1 | D4: 1.0087022 | E4: 1.0174801 | F4: 1.0263345 | G4: 1.0352658 | H4: 1.0442749 | I4: 1.0533624 | J4: 1.062529 | K4: 1.0717754 | L4: 1.0811022 | M4: 1.0905102 | N4: 1.1 | O4: 1.108005 | P4: 1.1160683 | Q4: 1.1241903 | R4: 1.1323713 | S4: 1.140612 | T4: 1.1489125 | U4: 1.1572735 | V4: 1.1656953 | W4: 1.1741785 | X4: 1.1827233 | Y4: 1.1913303 | Z4: 1.2
A6: COHORT SIZE | C6: 10000
A8: Leaky Bucket + Steady Cohort
B9: COHORT | C9: 1 | D9: =C9+1 -> 2 | E9: =D9+1 -> 3 | F9: =E9+1 -> 4 | G9: =F9+1 -> 5 | H9: =G9+1 -> 6 | I9: =H9+1 -> 7 | J9: =I9+1 -> 8 | K9: =J9+1 -> 9 | ... Z9: =Y9+1 -> 24
B10: 1 | C10: =$C$6*C$3 -> 10000 | D10: =$C$6*D$3 -> 9546.2308 | E10: =$C$6*E$3 -> 9113.0523 | F10: =$C$6*F$3 -> 8699.5301 | G10: =$C$6*G$3 -> 8304.7723 | H10: =$C$6*H$3 -> 7927.9273 | I10: =$C$6*I$3 -> 7568.1824 | J10: =$C$6*J$3 -> 7224.7616 | ... Z10: =$C$6*Z$3 -> 4500
B11: =B10+1 -> 2 | D11: =$C$6*C$3 -> 10000 | E11: =$C$6*D$3 -> 9546.2308 | F11: =$C$6*E$3 -> 9113.0523 | G11: =$C$6*F$3 -> 8699.5301 | H11: =$C$6*G$3 -> 8304.7723 | I11: =$C$6*H$3 -> 7927.9273 | J11: =$C$6*I$3 -> 7568.1824 | K11: =$C$6*J$3 -> 7224.7616 | ... Z11: =$C$6*Y$3 -> 4609.1843
B12: =B11+1 -> 3 | E12: =$C$6*C$3 -> 10000 | F12: =$C$6*D$3 -> 9546.2308 | G12: =$C$6*E$3 -> 9113.0523 | H12: =$C$6*F$3 -> 8699.5301 | I12: =$C$6*G$3 -> 8304.7723 | J12: =$C$6*H$3 -> 7927.9273 | K12: =$C$6*I$3 -> 7568.1824 | L12: =$C$6*J$3 -> 7224.7616 | ... Z12: =$C$6*X$3 -> 4721.0178
B13: =B12+1 -> 4 | F13: =$C$6*C$3 -> 10000 | G13: =$C$6*D$3 -> 9546.2308 | H13: =$C$6*E$3 -> 9113.0523 | I13: =$C$6*F$3 -> 8699.5301 | J13: =$C$6*G$3 -> 8304.7723 | K13: =$C$6*H$3 -> 7927.9273 | L13: =$C$6*I$3 -> 7568.1824 | M13: =$C$6*J$3 -> 7224.7616 | ... Z13: =$C$6*W$3 -> 4835.5647
B14: =B13+1 -> 5 | G14: =$C$6*C$3 -> 10000 | H14: =$C$6*D$3 -> 9546.2308 | I14: =$C$6*E$3 -> 9113.0523 | J14: =$C$6*F$3 -> 8699.5301 | K14: =$C$6*G$3 -> 8304.7723 | L14: =$C$6*H$3 -> 7927.9273 | M14: =$C$6*I$3 -> 7568.1824 | N14: =$C$6*J$3 -> 7224.7616 | ... Z14: =$C$6*V$3 -> 4952.8909
B15: =B14+1 -> 6 | H15: =$C$6*C$3 -> 10000 | I15: =$C$6*D$3 -> 9546.2308 | J15: =$C$6*E$3 -> 9113.0523 | K15: =$C$6*F$3 -> 8699.5301 | L15: =$C$6*G$3 -> 8304.7723 | M15: =$C$6*H$3 -> 7927.9273 | N15: =$C$6*I$3 -> 7568.1824 | O15: =$C$6*J$3 -> 7224.7616 | ... Z15: =$C$6*U$3 -> 5073.0638
B16: =B15+1 -> 7 | I16: =$C$6*C$3 -> 10000 | J16: =$C$6*D$3 -> 9546.2308 | K16: =$C$6*E$3 -> 9113.0523 | L16: =$C$6*F$3 -> 8699.5301 | M16: =$C$6*G$3 -> 8304.7723 | N16: =$C$6*H$3 -> 7927.9273 | O16: =$C$6*I$3 -> 7568.1824 | P16: =$C$6*J$3 -> 7224.7616 | ... Z16: =$C$6*T$3 -> 5196.1524
B17: =B16+1 -> 8 | J17: =$C$6*C$3 -> 10000 | K17: =$C$6*D$3 -> 9546.2308 | L17: =$C$6*E$3 -> 9113.0523 | M17: =$C$6*F$3 -> 8699.5301 | N17: =$C$6*G$3 -> 8304.7723 | O17: =$C$6*H$3 -> 7927.9273 | P17: =$C$6*I$3 -> 7568.1824 | Q17: =$C$6*J$3 -> 7224.7616 | ... Z17: =$C$6*S$3 -> 5322.2276
B18: =B17+1 -> 9 | K18: =$C$6*C$3 -> 10000 | L18: =$C$6*D$3 -> 9546.2308 | M18: =$C$6*E$3 -> 9113.0523 | N18: =$C$6*F$3 -> 8699.5301 | O18: =$C$6*G$3 -> 8304.7723 | P18: =$C$6*H$3 -> 7927.9273 | Q18: =$C$6*I$3 -> 7568.1824 | R18: =$C$6*J$3 -> 7224.7616 | ... Z18: =$C$6*R$3 -> 5451.3618
B19: =B18+1 -> 10 | L19: =$C$6*C$3 -> 10000 | M19: =$C$6*D$3 -> 9546.2308 | N19: =$C$6*E$3 -> 9113.0523 | O19: =$C$6*F$3 -> 8699.5301 | P19: =$C$6*G$3 -> 8304.7723 | Q19: =$C$6*H$3 -> 7927.9273 | R19: =$C$6*I$3 -> 7568.1824 | S19: =$C$6*J$3 -> 7224.7616 | ... Z19: =$C$6*Q$3 -> 5583.6292
B20: =B19+1 -> 11 | M20: =$C$6*C$3 -> 10000 | N20: =$C$6*D$3 -> 9546.2308 | O20: =$C$6*E$3 -> 9113.0523 | P20: =$C$6*F$3 -> 8699.5301 | Q20: =$C$6*G$3 -> 8304.7723 | R20: =$C$6*H$3 -> 7927.9273 | S20: =$C$6*I$3 -> 7568.1824 | T20: =$C$6*J$3 -> 7224.7616 | ... Z20: =$C$6*P$3 -> 5719.1058
B21: =B20+1 -> 12 | N21: =$C$6*C$3 -> 10000 | O21: =$C$6*D$3 -> 9546.2308 | P21: =$C$6*E$3 -> 9113.0523 | Q21: =$C$6*F$3 -> 8699.5301 | R21: =$C$6*G$3 -> 8304.7723 | S21: =$C$6*H$3 -> 7927.9273 | T21: =$C$6*I$3 -> 7568.1824 | U21: =$C$6*J$3 -> 7224.7616 | ... Z21: =$C$6*O$3 -> 5857.8695
B22: =B21+1 -> 13 | O22: =$C$6*C$3 -> 10000 | P22: =$C$6*D$3 -> 9546.2308 | Q22: =$C$6*E$3 -> 9113.0523 | R22: =$C$6*F$3 -> 8699.5301 | S22: =$C$6*G$3 -> 8304.7723 | T22: =$C$6*H$3 -> 7927.9273 | U22: =$C$6*I$3 -> 7568.1824 | V22: =$C$6*J$3 -> 7224.7616 | ... Z22: =$C$6*N$3 -> 6000
B23: =B22+1 -> 14 | P23: =$C$6*C$3 -> 10000 | Q23: =$C$6*D$3 -> 9546.2308 | R23: =$C$6*E$3 -> 9113.0523 | S23: =$C$6*F$3 -> 8699.5301 | T23: =$C$6*G$3 -> 8304.7723 | U23: =$C$6*H$3 -> 7927.9273 | V23: =$C$6*I$3 -> 7568.1824 | W23: =$C$6*J$3 -> 7224.7616 | ... Z23: =$C$6*M$3 -> 6285.2031
B24: =B23+1 -> 15 | Q24: =$C$6*C$3 -> 10000 | R24: =$C$6*D$3 -> 9546.2308 | S24: =$C$6*E$3 -> 9113.0523 | T24: =$C$6*F$3 -> 8699.5301 | U24: =$C$6*G$3 -> 8304.7723 | V24: =$C$6*H$3 -> 7927.9273 | W24: =$C$6*I$3 -> 7568.1824 | X24: =$C$6*J$3 -> 7224.7616 | ... Z24: =$C$6*L$3 -> 6583.9631
B25: =B24+1 -> 16 | R25: =$C$6*C$3 -> 10000 | S25: =$C$6*D$3 -> 9546.2308 | T25: =$C$6*E$3 -> 9113.0523 | U25: =$C$6*F$3 -> 8699.5301 | V25: =$C$6*G$3 -> 8304.7723 | W25: =$C$6*H$3 -> 7927.9273 | X25: =$C$6*I$3 -> 7568.1824 | Y25: =$C$6*J$3 -> 7224.7616 | Z25: =$C$6*K$3 -> 6896.9242
B26: =B25+1 -> 17 | S26: =$C$6*C$3 -> 10000 | T26: =$C$6*D$3 -> 9546.2308 | U26: =$C$6*E$3 -> 9113.0523 | V26: =$C$6*F$3 -> 8699.5301 | W26: =$C$6*G$3 -> 8304.7723 | X26: =$C$6*H$3 -> 7927.9273 | Y26: =$C$6*I$3 -> 7568.1824 | Z26: =$C$6*J$3 -> 7224.7616
B27: =B26+1 -> 18 | T27: =$C$6*C$3 -> 10000 | U27: =$C$6*D$3 -> 9546.2308 | V27: =$C$6*E$3 -> 9113.0523 | W27: =$C$6*F$3 -> 8699.5301 | X27: =$C$6*G$3 -> 8304.7723 | Y27: =$C$6*H$3 -> 7927.9273 | Z27: =$C$6*I$3 -> 7568.1824
B28: =B27+1 -> 19 | U28: =$C$6*C$3 -> 10000 | V28: =$C$6*D$3 -> 9546.2308 | W28: =$C$6*E$3 -> 9113.0523 | X28: =$C$6*F$3 -> 8699.5301 | Y28: =$C$6*G$3 -> 8304.7723 | Z28: =$C$6*H$3 -> 7927.9273
B29: =B28+1 -> 20 | V29: =$C$6*C$3 -> 10000 | W29: =$C$6*D$3 -> 9546.2308 | X29: =$C$6*E$3 -> 9113.0523 | Y29: =$C$6*F$3 -> 8699.5301 | Z29: =$C$6*G$3 -> 8304.7723
B30: =B29+1 -> 21 | W30: =$C$6*C$3 -> 10000 | X30: =$C$6*D$3 -> 9546.2308 | Y30: =$C$6*E$3 -> 9113.0523 | Z30: =$C$6*F$3 -> 8699.5301
B31: =B30+1 -> 22 | X31: =$C$6*C$3 -> 10000 | Y31: =$C$6*D$3 -> 9546.2308 | Z31: =$C$6*E$3 -> 9113.0523
B32: =B31+1 -> 23 | Y32: =$C$6*C$3 -> 10000 | Z32: =$C$6*D$3 -> 9546.2308
B33: =B32+1 -> 24 | Z33: =$C$6*C$3 -> 10000
B34: Total | C34: =SUM(C10:C33) -> 10000 | D34: =SUM(D10:D33) -> 19546.231 | E34: =SUM(E10:E33) -> 28659.283 | F34: =SUM(F10:F33) -> 37358.813 | G34: =SUM(G10:G33) -> 45663.586 | H34: =SUM(H10:H33) -> 53591.513 | I34: =SUM(I10:I33) -> 61159.695 | J34: =SUM(J10:J33) -> 68384.457 | ... Z34: =SUM(Z10:Z33) -> 155972.61
A35: Net Negative + Steady Cohort
B36: COHORT | C36: 1 | D36: =C36+1 -> 2 | E36: =D36+1 -> 3 | F36: =E36+1 -> 4 | G36: =F36+1 -> 5 | H36: =G36+1 -> 6 | I36: =H36+1 -> 7 | J36: =I36+1 -> 8 | K36: =J36+1 -> 9 | ... Z36: =Y36+1 -> 24
B37: 1 | C37: =$C$6*C$4 -> 10000 | D37: =$C$6*D$4 -> 10087.022 | E37: =$C$6*E$4 -> 10174.801 | F37: =$C$6*F$4 -> 10263.345 | G37: =$C$6*G$4 -> 10352.658 | H37: =$C$6*H$4 -> 10442.749 | I37: =$C$6*I$4 -> 10533.624 | J37: =$C$6*J$4 -> 10625.29 | ... Z37: =$C$6*Z$4 -> 12000
B38: =B37+1 -> 2 | D38: =$C$6*C$4 -> 10000 | E38: =$C$6*D$4 -> 10087.022 | F38: =$C$6*E$4 -> 10174.801 | G38: =$C$6*F$4 -> 10263.345 | H38: =$C$6*G$4 -> 10352.658 | I38: =$C$6*H$4 -> 10442.749 | J38: =$C$6*I$4 -> 10533.624 | K38: =$C$6*J$4 -> 10625.29 | ... Z38: =$C$6*Y$4 -> 11913.303
B39: =B38+1 -> 3 | E39: =$C$6*C$4 -> 10000 | F39: =$C$6*D$4 -> 10087.022 | G39: =$C$6*E$4 -> 10174.801 | H39: =$C$6*F$4 -> 10263.345 | I39: =$C$6*G$4 -> 10352.658 | J39: =$C$6*H$4 -> 10442.749 | K39: =$C$6*I$4 -> 10533.624 | L39: =$C$6*J$4 -> 10625.29 | ... Z39: =$C$6*X$4 -> 11827.233
B40: =B39+1 -> 4 | F40: =$C$6*C$4 -> 10000 | G40: =$C$6*D$4 -> 10087.022 | H40: =$C$6*E$4 -> 10174.801 | I40: =$C$6*F$4 -> 10263.345 | J40: =$C$6*G$4 -> 10352.658 | K40: =$C$6*H$4 -> 10442.749 | L40: =$C$6*I$4 -> 10533.624 | M40: =$C$6*J$4 -> 10625.29 | ... Z40: =$C$6*W$4 -> 11741.785
B41: =B40+1 -> 5 | G41: =$C$6*C$4 -> 10000 | H41: =$C$6*D$4 -> 10087.022 | I41: =$C$6*E$4 -> 10174.801 | J41: =$C$6*F$4 -> 10263.345 | K41: =$C$6*G$4 -> 10352.658 | L41: =$C$6*H$4 -> 10442.749 | M41: =$C$6*I$4 -> 10533.624 | N41: =$C$6*J$4 -> 10625.29 | ... Z41: =$C$6*V$4 -> 11656.953
B42: =B41+1 -> 6 | H42: =$C$6*C$4 -> 10000 | I42: =$C$6*D$4 -> 10087.022 | J42: =$C$6*E$4 -> 10174.801 | K42: =$C$6*F$4 -> 10263.345 | L42: =$C$6*G$4 -> 10352.658 | M42: =$C$6*H$4 -> 10442.749 | N42: =$C$6*I$4 -> 10533.624 | O42: =$C$6*J$4 -> 10625.29 | ... Z42: =$C$6*U$4 -> 11572.735
B43: =B42+1 -> 7 | I43: =$C$6*C$4 -> 10000 | J43: =$C$6*D$4 -> 10087.022 | K43: =$C$6*E$4 -> 10174.801 | L43: =$C$6*F$4 -> 10263.345 | M43: =$C$6*G$4 -> 10352.658 | N43: =$C$6*H$4 -> 10442.749 | O43: =$C$6*I$4 -> 10533.624 | P43: =$C$6*J$4 -> 10625.29 | ... Z43: =$C$6*T$4 -> 11489.125
...

Sheet Calcs 2
A2: RETENTION CURVE | B2: 1 | C2: =B2+1 -> 2 | D2: =C2+1 -> 3 | E2: =D2+1 -> 4 | F2: =E2+1 -> 5 | G2: =F2+1 -> 6 | H2: =G2+1 -> 7 | I2: =H2+1 -> 8 | J2: =I2+1 -> 9 | ... Y2: =X2+1 -> 24
A3: Leaky Bucket | B3: ='Calcs 1'!C3 -> 1 | C3: ='Calcs 1'!D3 -> 0.95462308 | D3: ='Calcs 1'!E3 -> 0.91130523 | E3: ='Calcs 1'!F3 -> 0.86995301 | F3: ='Calcs 1'!G3 -> 0.83047723 | G3: ='Calcs 1'!H3 -> 0.79279273 | H3: ='Calcs 1'!I3 -> 0.75681824 | I3: ='Calcs 1'!J3 -> 0.72247616 | ... Y3: ='Calcs 1'!Z3 -> 0.45
A4: Net Negative | B4: ='Calcs 1'!C4 -> 1 | C4: ='Calcs 1'!D4 -> 1.0087022 | D4: ='Calcs 1'!E4 -> 1.0174801 | E4: ='Calcs 1'!F4 -> 1.0263345 | F4: ='Calcs 1'!G4 -> 1.0352658 | G4: ='Calcs 1'!H4 -> 1.0442749 | H4: ='Calcs 1'!I4 -> 1.0533624 | I4: ='Calcs 1'!J4 -> 1.062529 | ... Y4: ='Calcs 1'!Z4 -> 1.2
A6: Leaky Bucket + Growing Cohort
A8: CMGR | B8: SIZE | C8: COHORT | D8: 1 | E8: =D8+1 -> 2 | F8: =E8+1 -> 3 | G8: =F8+1 -> 4 | H8: =G8+1 -> 5 | I8: =H8+1 -> 6 | J8: =I8+1 -> 7 | K8: =J8+1 -> 8 | L8: =K8+1 -> 9 | ... AA8: =Z8+1 -> 24
A9: 0.038479488 | B9: 10000 | C9: 1 | D9: =B9 -> 10000 | E9: =$D$9*C3 -> 9546.2308 | F9: =$D$9*D3 -> 9113.0523 | G9: =$D$9*E3 -> 8699.5301 | H9: =$D$9*F3 -> 8304.7723 | I9: =$D$9*G3 -> 7927.9273 | J9: =$D$9*H3 -> 7568.1824 | K9: =$D$9*I3 -> 7224.7616 | L9: =$D$9*J3 -> 6896.9242 | ... AA9: =$D$9*Y3 -> 4500
B10: =B9*(1+$A$9) -> 10384.795 | C10: =C9+1 -> 2 | E10: =B10 -> 10384.795 | F10: =$E$10*C3 -> 9913.5649 | G10: =$E$10*D3 -> 9463.7179 | H10: =$E$10*E3 -> 9034.2836 | I10: =$E$10*F3 -> 8624.3356 | J10: =$E$10*G3 -> 8232.9899 | K10: =$E$10*H3 -> 7859.4022 | L10: =$E$10*I3 -> 7502.7668 | M10: =$E$10*J3 -> 7162.3143 | ... AA10: =$E$10*X3 -> 4786.5434
B11: =B10*(1+$A$9) -> 10784.396 | C11: =C10+1 -> 3 | F11: =B11 -> 10784.396 | G11: =$F$11*C$3 -> 10295.034 | H11: =$F$11*D$3 -> 9827.8769 | I11: =$F$11*E$3 -> 9381.9182 | J11: =$F$11*F$3 -> 8956.1957 | K11: =$F$11*G$3 -> 8549.7911 | L11: =$F$11*H$3 -> 8161.828 | M11: =$F$11*I$3 -> 7791.4694 | N11: =$F$11*J$3 -> 7437.9165 | ... AA11: =$F$11*W$3 -> 5091.3328
B12: =B11*(1+$A$9) -> 11199.375 | C12: =C11+1 -> 4 | G12: =B12 -> 11199.375 | H12: =$G$12*C3 -> 10691.181 | I12: =$G$12*D3 -> 10206.049 | J12: =$G$12*E3 -> 9742.9296 | K12: =$G$12*F3 -> 9300.8255 | L12: =$G$12*G3 -> 8878.7827 | M12: =$G$12*H3 -> 8475.8909 | N12: =$G$12*I3 -> 8091.2811 | O12: =$G$12*J3 -> 7724.1238 | ... AA12: =$G$12*V3 -> 5415.53
B13: =B12*(1+$A$9) -> 11630.321 | C13: =C12+1 -> 5 | H13: =B13 -> 11630.321 | I13: =$H$13*C3 -> 11102.573 | J13: =$H$13*D3 -> 10598.772 | K13: =$H$13*E3 -> 10117.833 | L13: =$H$13*F3 -> 9658.7165 | M13: =$H$13*G3 -> 9220.4337 | N13: =$H$13*H3 -> 8802.0389 | O13: =$H$13*I3 -> 8402.6295 | P13: =$H$13*J3 -> 8021.3441 | ... AA13: =$H$13*U3 -> 5760.3709
B14: =B13*(1+$A$9) -> 12077.85 | C14: =C13+1 -> 6 | I14: =B14 -> 12077.85 | J14: =$I$14*C3 -> 11529.794 | K14: =$I$14*D3 -> 11006.607 | L14: =$I$14*E3 -> 10507.162 | M14: =$I$14*F3 -> 10030.379 | N14: =$I$14*G3 -> 9575.2313 | O14: =$I$14*H3 -> 9140.7368 | P14: =$I$14*I3 -> 8725.9584 | Q14: =$I$14*J3 -> 8330.0013 | ... AA14: =$I$14*T3 -> 6127.1701
B15: =B14*(1+$A$9) -> 12542.599 | C15: =C14+1 -> 7 | J15: =B15 -> 12542.599 | K15: =$J$15*C3 -> 11973.455 | L15: =$J$15*D3 -> 11430.136 | M15: =$J$15*E3 -> 10911.472 | N15: =$J$15*F3 -> 10416.343 | O15: =$J$15*G3 -> 9943.6813 | P15: =$J$15*H3 -> 9492.4677 | Q15: =$J$15*I3 -> 9061.7288 | R15: =$J$15*J3 -> 8650.5355 | ... AA15: =$J$15*S3 -> 6517.3256
B16: =B15*(1+$A$9) -> 13025.232 | C16: =C15+1 -> 8 | K16: =B16 -> 13025.232 | L16: =$K$16*C3 -> 12434.187 | M16: =$K$16*D3 -> 11869.962 | N16: =$K$16*E3 -> 11331.34 | O16: =$K$16*F3 -> 10817.158 | P16: =$K$16*G3 -> 10326.309 | Q16: =$K$16*H3 -> 9857.733 | R16: =$K$16*I3 -> 9410.4195 | S16: =$K$16*J3 -> 8983.4037 | ... AA16: =$K$16*R3 -> 6932.3248
B17: =B16*(1+$A$9) -> 13526.436 | C17: =C16+1 -> 9 | L17: =B17 -> 13526.436 | M17: =$L$17*C3 -> 12912.648 | N17: =$L$17*D3 -> 12326.712 | O17: =$L$17*E3 -> 11767.364 | P17: =$L$17*F3 -> 11233.397 | Q17: =$L$17*G3 -> 10723.66 | R17: =$L$17*H3 -> 10237.054 | S17: =$L$17*I3 -> 9772.5276 | T17: =$L$17*J3 -> 9329.0804 | ... AA17: =$L$17*Q3 -> 7373.7496
B18: =B17*(1+$A$9) -> 14046.926 | C18: =C17+1 -> 10 | M18: =B18 -> 14046.926 | N18: =$M$18*C3 -> 13409.52 | O18: =$M$18*D3 -> 12801.038 | P18: =$M$18*E3 -> 12220.166 | Q18: =$M$18*F3 -> 11665.652 | R18: =$M$18*G3 -> 11136.301 | S18: =$M$18*H3 -> 10630.97 | T18: =$M$18*I3 -> 10148.569 | U18: =$M$18*J3 -> 9688.0587 | ... AA18: =$M$18*P3 -> 7843.2828
B19: =B18*(1+$A$9) -> 14587.445 | C19: =C18+1 -> 11 | N19: =B19 -> 14587.445 | O19: =$N$19*C3 -> 13925.512 | P19: =$N$19*D3 -> 13293.615 | Q19: =$N$19*E3 -> 12690.392 | R19: =$N$19*F3 -> 12114.541 | S19: =$N$19*G3 -> 11564.82 | T19: =$N$19*H3 -> 11040.044 | U19: =$N$19*I3 -> 10539.081 | V19: =$N$19*J3 -> 10060.85 | ... AA19: =$N$19*O3 -> 8342.714
B20: =B19*(1+$A$9) -> 15148.762 | C20: =C19+1 -> 12 | O20: =B20 -> 15148.762 | P20: =$O$20*C3 -> 14461.358 | Q20: =$O$20*D3 -> 13805.146 | R20: =$O$20*E3 -> 13178.711 | S20: =$O$20*F3 -> 12580.702 | T20: =$O$20*G3 -> 12009.829 | U20: =$O$20*H3 -> 11464.86 | V20: =$O$20*I3 -> 10944.62 | W20: =$O$20*J3 -> 10447.987 | ... AA20: =$O$20*N3 -> 8873.9472
B21: =B20*(1+$A$9) -> 15731.679 | C21: =C20+1 -> 13 | P21: =B21 -> 15731.679 | Q21: =$P$21*C3 -> 15017.824 | R21: =$P$21*D3 -> 14336.361 | S21: =$P$21*E3 -> 13685.821 | T21: =$P$21*F3 -> 13064.801 | U21: =$P$21*G3 -> 12471.961 | V21: =$P$21*H3 -> 11906.022 | W21: =$P$21*I3 -> 11365.763 | X21: =$P$21*J3 -> 10850.02 | ... AA21: =$P$21*M3 -> 9439.0074
B22: =B21*(1+$A$9) -> 16337.026 | C22: =C21+1 -> 14 | Q22: =B22 -> 16337.026 | R22: =$Q$22*C3 -> 15595.702 | S22: =$Q$22*D3 -> 14888.017 | T22: =$Q$22*E3 -> 14212.445 | U22: =$Q$22*F3 -> 13567.528 | V22: =$Q$22*G3 -> 12951.875 | W22: =$Q$22*H3 -> 12364.159 | X22: =$Q$22*I3 -> 11803.112 | Y22: =$Q$22*J3 -> 11267.523 | ... AA22: =$Q$22*L3 -> 10268.153
B23: =B22*(1+$A$9) -> 16965.666 | C23: =C22+1 -> 15 | R23: =B23 -> 16965.666 | S23: =$R$23*C3 -> 16195.817 | T23: =$R$23*D3 -> 15460.9 | U23: =$R$23*E3 -> 14759.332 | V23: =$R$23*F3 -> 14089.6 | W23: =$R$23*G3 -> 13450.257 | X23: =$R$23*H3 -> 12839.926 | Y23: =$R$23*I3 -> 12257.29 | Z23: =$R$23*J3 -> 11701.092 | AA23: =$R$23*K3 -> 11170.132
B24: =B23*(1+$A$9) -> 17618.496 | C24: =C23+1 -> 16 | S24: =B24 -> 17618.496 | T24: =$S$24*C3 -> 16819.023 | U24: =$S$24*D3 -> 16055.828 | V24: =$S$24*E3 -> 15327.264 | W24: =$S$24*F3 -> 14631.76 | X24: =$S$24*G3 -> 13967.816 | Y24: =$S$24*H3 -> 13334 | Z24: =$S$24*I3 -> 12728.944 | AA24: =$S$24*J3 -> 12151.344
B25: =B24*(1+$A$9) -> 18296.447 | C25: =C24+1 -> 17 | T25: =B25 -> 18296.447 | U25: =$T$25*C3 -> 17466.211 | V25: =$T$25*D3 -> 16673.648 | W25: =$T$25*E3 -> 15917.049 | X25: =$T$25*F3 -> 15194.783 | Y25: =$T$25*G3 -> 14505.29 | Z25: =$T$25*H3 -> 13847.085 | AA25: =$T$25*I3 -> 13218.747
B26: =B25*(1+$A$9) -> 19000.485 | C26: =C25+1 -> 18 | U26: =B26 -> 19000.485 | V26: =$U$26*C3 -> 18138.302 | W26: =$U$26*D3 -> 17315.242 | X26: =$U$26*E3 -> 16529.529 | Y26: =$U$26*F3 -> 15779.47 | Z26: =$U$26*G3 -> 15063.446 | AA26: =$U$26*H3 -> 14379.914
B27: =B26*(1+$A$9) -> 19731.614 | C27: =C26+1 -> 19 | V27: =B27 -> 19731.614 | W27: =$V$27*C3 -> 18836.254 | X27: =$V$27*D3 -> 17981.523 | Y27: =$V$27*E3 -> 17165.577 | Z27: =$V$27*F3 -> 16386.656 | AA27: =$V$27*G3 -> 15643.08
B28: =B27*(1+$A$9) -> 20490.876 | C28: =C27+1 -> 20 | W28: =B28 -> 20490.876 | X28: =$W$28*C3 -> 19561.064 | Y28: =$W$28*D3 -> 18673.443 | Z28: =$W$28*E3 -> 17826.1 | AA28: =$W$28*F3 -> 17017.206
B29: =B28*(1+$A$9) -> 21279.355 | C29: =C28+1 -> 21 | X29: =B29 -> 21279.355 | Y29: =$X$29*C3 -> 20313.763 | Z29: =$X$29*D3 -> 19391.987 | AA29: =$X$29*E3 -> 18512.039
B30: =B29*(1+$A$9) -> 22098.174 | C30: =C29+1 -> 22 | Y30: =B30 -> 22098.174 | Z30: =Y30*C3 -> 21095.427 | AA30: =Z30*D3 -> 19224.373
B31: =B30*(1+$A$9) -> 22948.5 | C31: =C30+1 -> 23 | Z31: =B31 -> 22948.5 | AA31: =$Z$31*C3 -> 21907.168
B32: =B31*(1+$A$9) -> 23831.547 | C32: =C31+1 -> 24 | AA32: =B32 -> 23831.547
C33: Total | D33: =SUM(D9:D32) -> 10000 | E33: =SUM(E9:E32) -> 19931.026 | F33: =SUM(F9:F32) -> 29811.014 | G33: =SUM(G9:G32) -> 39657.656 | H33: =SUM(H9:H32) -> 49488.435 | I33: =SUM(I9:I32) -> 59320.652 | J33: =SUM(J9:J32) -> 69171.463 | K33: =SUM(K9:K32) -> 79057.907 | ... AA33: =SUM(AA9:AA32) -> 264327
A35: Net Negative + Growing Cohort
A37: CMGR | B37: SIZE | C37: COHORT | D37: 1 | E37: =D37+1 -> 2 | F37: =E37+1 -> 3 | G37: =F37+1 -> 4 | H37: =G37+1 -> 5 | I37: =H37+1 -> 6 | J37: =I37+1 -> 7 | K37: =J37+1 -> 8 | L37: =K37+1 -> 9 | ... AA37: =Z37+1 -> 24
A38: 0.038479488 | B38: 10000 | C38: 1 | D38: =B38 -> 10000 | E38: =$D$9*C4 -> 10087.022 | F38: =$D$9*D4 -> 10174.801 | G38: =$D$9*E4 -> 10263.345 | H38: =$D$9*F4 -> 10352.658 | I38: =$D$9*G4 -> 10442.749 | J38: =$D$9*H4 -> 10533.624 | K38: =$D$9*I4 -> 10625.29 | L38: =$D$9*J4 -> 10717.754 | ... AA38: =$D$9*Y4 -> 12000
B39: =B38*(1+$A$9) -> 10384.795 | C39: =C38+1 -> 2 | E39: =B39 -> 10384.795 | F39: =$E$10*C4 -> 10475.166 | G39: =$E$10*D4 -> 10566.323 | H39: =$E$10*E4 -> 10658.273 | I39: =$E$10*F4 -> 10751.023 | J39: =$E$10*G4 -> 10844.581 | K39: =$E$10*H4 -> 10938.953 | L39: =$E$10*I4 -> 11034.146 | M39: =$E$10*J4 -> 11130.167 | ... AA39: =$E$10*X4 -> 12371.721
B40: =B39*(1+$A$9) -> 10784.396 | C40: =C39+1 -> 3 | F40: =B40 -> 10784.396 | G40: =$F$40*C4 -> 10878.245 | H40: =$F$40*D4 -> 10972.909 | I40: =$F$40*E4 -> 11068.398 | J40: =$F$40*F4 -> 11164.717 | K40: =$F$40*G4 -> 11261.875 | L40: =$F$40*H4 -> 11359.878 | M40: =$F$40*I4 -> 11458.734 | N40: =$F$40*J4 -> 11558.45 | ... AA40: =$F$40*W4 -> 12754.957
B41: =B40*(1+$A$9) -> 11199.375 | C41: =C40+1 -> 4 | G41: =B41 -> 11199.375 | H41: =$G$12*C4 -> 11296.834 | I41: =$G$12*D4 -> 11395.141 | J41: =$G$12*E4 -> 11494.304 | K41: =$G$12*F4 -> 11594.33 | L41: =$G$12*G4 -> 11695.226 | M41: =$G$12*H4 -> 11797 | N41: =$G$12*I4 -> 11899.66 | O41: =$G$12*J4 -> 12003.214 | ... AA41: =$G$12*V4 -> 13150.064
B42: =B41*(1+$A$9) -> 11630.321 | C42: =C41+1 -> 5 | H42: =B42 -> 11630.321 | I42: =$H$13*C4 -> 11731.53 | J42: =$H$13*D4 -> 11833.62 | K42: =$H$13*E4 -> 11936.599 | L42: =$H$13*F4 -> 12040.474 | M42: =$H$13*G4 -> 12145.253 | N42: =$H$13*H4 -> 12250.943 | O42: =$H$13*I4 -> 12357.553 | P42: =$H$13*J4 -> 12465.091 | ... AA42: =$H$13*U4 -> 13557.411
B43: =B42*(1+$A$9) -> 12077.85 | C43: =C42+1 -> 6 | I43: =B43 -> 12077.85 | J43: =$I$14*C4 -> 12182.953 | K43: =$I$14*D4 -> 12288.972 | L43: =$I$14*E4 -> 12395.913 | M43: =$I$14*F4 -> 12503.785 | N43: =$I$14*G4 -> 12612.596 | O43: =$I$14*H4 -> 12722.353 | P43: =$I$14*I4 -> 12833.066 | Q43: =$I$14*J4 -> 12944.742 | ... AA43: =$I$14*T4 -> 13977.375
B44: =B43*(1+$A$9) -> 12542.599 | C44: =C43+1 -> 7 | J44: =B44 -> 12542.599 | K44: =$J$15*C4 -> 12651.747 | L44: =$J$15*D4 -> 12761.845 | M44: =$J$15*E4 -> 12872.902 | N44: =$J$15*F4 -> 12984.924 | O44: =$J$15*G4 -> 13097.922 | P44: =$J$15*H4 -> 13211.903 | Q44: =$J$15*I4 -> 13326.875 | R44: =$J$15*J4 -> 13442.849 | ... AA44: =$J$15*S4 -> 14410.349
B45: =B44*(1+$A$9) -> 13025.232 | C45: =C44+1 -> 8 | K45: =B45 -> 13025.232 | L45: =$K$16*C4 -> 13138.58 | M45: =$K$16*D4 -> 13252.915 | N45: =$K$16*E4 -> 13368.244 | O45: =$K$16*F4 -> 13484.578 | P45: =$K$16*G4 -> 13601.923 | Q45: =$K$16*H4 -> 13720.29 | R45: =$K$16*I4 -> 13839.687 | S45: =$K$16*J4 -> 13960.123 | ... AA45: =$K$16*R4 -> 14856.735
...

Sheet Calcs 3
C2: Growing Cohort | D2: Steady Cohort
B3: 1 | C3: ='Calcs 2'!B9 -> 10000 | D3: ='Calcs 1'!C6 -> 10000
B4: =B3+1 -> 2 | C4: ='Calcs 2'!B10 -> 10384.795 | D4: =$D$3 -> 10000
B5: =B4+1 -> 3 | C5: ='Calcs 2'!B11 -> 10784.396 | D5: =$D$3 -> 10000
B6: =B5+1 -> 4 | C6: ='Calcs 2'!B12 -> 11199.375 | D6: =$D$3 -> 10000
B7: =B6+1 -> 5 | C7: ='Calcs 2'!B13 -> 11630.321 | D7: =$D$3 -> 10000
B8: =B7+1 -> 6 | C8: ='Calcs 2'!B14 -> 12077.85 | D8: =$D$3 -> 10000
B9: =B8+1 -> 7 | C9: ='Calcs 2'!B15 -> 12542.599 | D9: =$D$3 -> 10000
B10: =B9+1 -> 8 | C10: ='Calcs 2'!B16 -> 13025.232 | D10: =$D$3 -> 10000
B11: =B10+1 -> 9 | C11: ='Calcs 2'!B17 -> 13526.436 | D11: =$D$3 -> 10000
B12: =B11+1 -> 10 | C12: ='Calcs 2'!B18 -> 14046.926 | D12: =$D$3 -> 10000
B13: =B12+1 -> 11 | C13: ='Calcs 2'!B19 -> 14587.445 | D13: =$D$3 -> 10000
B14: =B13+1 -> 12 | C14: ='Calcs 2'!B20 -> 15148.762 | D14: =$D$3 -> 10000
B15: =B14+1 -> 13 | C15: ='Calcs 2'!B21 -> 15731.679 | D15: =$D$3 -> 10000
... B26: =B25+1 -> 24 | C26: ='Calcs 2'!B32 -> 23831.547 | D26: =$D$3 -> 10000
